<?xml version="1.0"?>
<robot xmlns:xacro="http://www.ros.org/wiki/xacro">

    <xacro:include filename="inertial_macros.xacro" />

    <!-- Materials -->

        <material name="black">
            <color rgba="0 0 0 1"/>
        </material>

        <material name="white">
            <color rgba="1 1 1 1"/>
        </material>

    <!-- Links -->

        <link name="base_link">

        </link>

      

        <joint name="main_joint" type="fixed">
            <origin xyz="0 0 0"/>
            <parent link="base_link"/>
            <child link="main_link"/>
        </joint>


        <link name="main_link">
            <visual>
                <origin xyz="0 0 0.025"/>
                <geometry>
                    <box size="0.05 0.05 0.05"/>
                </geometry>
                <material name="white"/>
            </visual>
            <collision>
                <origin xyz="0 0 0.025"/>
                <geometry>
                    <box size="0.05 0.05 0.05"/>
                </geometry>
            </collision>
            <xacro:inertial_box mass="10" x="0.05" y="0.05" z="0.05">
                <origin xyz="0 0 0.025" rpy="0.0 0.0 0.0"/>
            </xacro:inertial_box>
        </link>

        <gazebo reference="main_link">
            <material>Gazebo/White</material>   
        </gazebo>


        <joint name="arm_joint" type="revolute">
            <origin xyz="0 0 0.05"/>
            <parent link="main_link"/>
            <child link="arm_link"/>
            <axis xyz="0 0 1"/>
            <limit lower="0" upper="${pi}" effort="100" velocity="10"/>
        </joint>

        <link name="arm_link">
            <visual>
                <origin xyz="0.05 0 0"/>
                <geometry>
                    <box size="0.1 0.02 0.01"/>
                </geometry>
                <material name="black"/>
            </visual>
            <collision>
                <origin xyz="0.05 0 0"/>
                <geometry>
                    <box size="0.1 0.02 0.01"/>
                </geometry>
            </collision>
            <xacro:inertial_box mass="0.1" x="0.1" y="0.02" z="0.01">
                <origin xyz="0.05 0 0" rpy="0.0 0.0 0.0"/>
            </xacro:inertial_box>
        </link>

        <gazebo reference="arm_link">
            <material>Gazebo/Black</material>
        </gazebo>

</robot>